<robot
  name="final_description">
  <link
    name="base_link">
    <inertial>
      <origin
        xyz="-0.0542102930126108 -0.00147372643899868 0.030052049722662"
        rpy="0 0 0" />
      <mass
        value="12.6996504557446" />
      <inertia
        ixx="0.204547339739001"
        ixy="-0.00137510220264843"
        ixz="-0.0219088420664967"
        iyy="0.18075396064092"
        iyz="0.000599165089979215"
        izz="0.272229743771322" />
    </inertial>
    <visual>
      <origin
        xyz="0 0 0"
        rpy="0 0 0" />
      <geometry>
        <mesh
          filename="package://final_description/meshes/base_link.STL" />
      </geometry>
      <material
        name="">
        <color
          rgba="0.996078431372549 0.870588235294118 0.76078431372549 1" />
      </material>
    </visual>
    <collision>
      <origin
        xyz="0 0 0"
        rpy="0 0 0" />
      <geometry>
        <mesh
          filename="package://final_description/meshes/base_link.STL" />
      </geometry>
    </collision>
  </link>
  <link
    name="base_laser">
    <inertial>
      <origin
        xyz="0.0127 1.27087771103731E-19 -0.0254"
        rpy="0 0 0" />
      <mass
        value="0.7521662376" />
      <inertia
        ixx="0.000980644880738574"
        ixy="-2.68989534912001E-19"
        ixz="-1.37318069412529E-21"
        iyy="0.00117272996047087"
        iyz="-7.16140114664618E-36"
        izz="0.0018298631279761" />
    </inertial>
    <visual>
      <origin
        xyz="0 0 0"
        rpy="0 0 0" />
      <geometry>
        <mesh
          filename="package://final_description/meshes/base_laser.STL" />
      </geometry>
      <material
        name="">
        <color
          rgba="0.250980392156863 0.250980392156863 0.250980392156863 1" />
      </material>
    </visual>
    <collision>
      <origin
        xyz="0 0 0"
        rpy="0 0 0" />
      <geometry>
        <mesh
          filename="package://final_description/meshes/base_laser.STL" />
      </geometry>
    </collision>
  </link>
  <joint
    name="laser_joint"
    type="fixed">
    <origin
      xyz="-0.01095 0 0.25575"
      rpy="1.4539E-33 -3.4423E-17 -4.2237E-17" />
    <parent
      link="base_link" />
    <child
      link="base_laser" />
    <axis
      xyz="0 0 0" />
  </joint>
  <link
    name="left_wheel_link">
    <inertial>
      <origin
        xyz="-1.02697830889065E-05 0.0207696125417688 -1.29881572009938E-06"
        rpy="0 0 0" />
      <mass
        value="0.360809172043754" />
      <inertia
        ixx="0.00106675827256857"
        ixy="1.00199366250097E-07"
        ixz="-5.46170508888008E-09"
        iyy="0.00202538580830831"
        iyz="7.42904254207973E-09"
        izz="0.00106727492610413" />
    </inertial>
    <visual>
      <origin
        xyz="0 0 0"
        rpy="0 0 0" />
      <geometry>
        <mesh
          filename="package://final_description/meshes/left_wheel_link.STL" />
      </geometry>
      <material
        name="">
        <color
          rgba="0 0 0 1" />
      </material>
    </visual>
    <collision>
      <origin
        xyz="0 0 0"
        rpy="0 0 0" />
      <geometry>
        <mesh
          filename="package://final_description/meshes/left_wheel_link.STL" />
      </geometry>
    </collision>
  </link>
  <joint
    name="left_wheel_joint"
    type="continuous">
    <origin
      xyz="0 0.19979 0"
      rpy="0 -3.4423E-17 0" />
    <parent
      link="base_link" />
    <child
      link="left_wheel_link" />
    <axis
      xyz="0 -1 0" />
  </joint>
  <link
    name="right_wheel_link">
    <inertial>
      <origin
        xyz="-7.84481351270849E-06 -0.0207696125417685 -2.84905793875717E-06"
        rpy="0 0 0" />
      <mass
        value="0.360809172043695" />
      <inertia
        ixx="0.00106697353985248"
        ixy="-9.44069048271625E-08"
        ixz="-2.70312200163111E-07"
        iyy="0.00202538582183835"
        iyz="-1.71229823500415E-08"
        izz="0.00106705967235024" />
    </inertial>
    <visual>
      <origin
        xyz="0 0 0"
        rpy="0 0 0" />
      <geometry>
        <mesh
          filename="package://final_description/meshes/right_wheel_link.STL" />
      </geometry>
      <material
        name="">
        <color
          rgba="1 1 1 1" />
      </material>
    </visual>
    <collision>
      <origin
        xyz="0 0 0"
        rpy="0 0 0" />
      <geometry>
        <mesh
          filename="package://final_description/meshes/right_wheel_link.STL" />
      </geometry>
    </collision>
  </link>
  <joint
    name="right_wheel_joint"
    type="continuous">
    <origin
      xyz="0 -0.20291 0"
      rpy="0 -3.4423E-17 0" />
    <parent
      link="base_link" />
    <child
      link="right_wheel_link" />
    <axis
      xyz="0 1 0" />
  </joint>
  <link
    name="rear_caster_link">
    <inertial>
      <origin
        xyz="-0.0145051914736939 1.27609826723198E-08 -0.0267008820899361"
        rpy="0 0 0" />
      <mass
        value="0.013967106304125" />
      <inertia
        ixx="3.65783748314741E-06"
        ixy="-6.1238514706205E-12"
        ixz="2.23670176886623E-06"
        iyy="6.47276824188859E-06"
        iyz="-1.48142589566201E-11"
        izz="3.77349384162539E-06" />
    </inertial>
    <visual>
      <origin
        xyz="0 0 0"
        rpy="0 0 0" />
      <geometry>
        <mesh
          filename="package://final_description/meshes/rear_caster_link.STL" />
      </geometry>
      <material
        name="">
        <color
          rgba="0.796078431372549 0.823529411764706 0.937254901960784 1" />
      </material>
    </visual>
    <collision>
      <origin
        xyz="0 0 0"
        rpy="0 0 0" />
      <geometry>
        <mesh
          filename="package://final_description/meshes/rear_caster_link.STL" />
      </geometry>
    </collision>
  </link>
  <joint
    name="rear_caster_joint"
    type="continuous">
    <origin
      xyz="-0.31195 0 -0.00604"
      rpy="-3.047E-33 -1.0831E-17 8.8518E-17" />
    <parent
      link="base_link" />
    <child
      link="rear_caster_link" />
    <axis
      xyz="0 0 -1" />
  </joint>
  <link
    name="left_caster_link">
    <inertial>
      <origin
        xyz="-0.0387985 0.0177164999999773 -0.0579120000000001"
        rpy="0 0 0" />
      <mass
        value="0.0814912470443748" />
      <inertia
        ixx="3.00969011069376E-05"
        ixy="-3.14217097100956E-20"
        ixz="5.59031486352145E-21"
        iyy="5.45189673119831E-05"
        iyz="3.60522749706849E-20"
        izz="3.00969011069376E-05" />
    </inertial>
    <visual>
      <origin
        xyz="0 0 0"
        rpy="0 0 0" />
      <geometry>
        <mesh
          filename="package://final_description/meshes/left_caster_link.STL" />
      </geometry>
      <material
        name="">
        <color
          rgba="0.796078431372549 0.823529411764706 0.937254901960784 1" />
      </material>
    </visual>
    <collision>
      <origin
        xyz="0 0 0"
        rpy="0 0 0" />
      <geometry>
        <mesh
          filename="package://final_description/meshes/left_caster_link.STL" />
      </geometry>
    </collision>
  </link>
  <joint
    name="left_caster_joint"
    type="continuous">
    <origin
      xyz="0 0 0"
      rpy="0 0 0" />
    <parent
      link="rear_caster_link" />
    <child
      link="left_caster_link" />
    <axis
      xyz="0 -1 0" />
  </joint>
  <link
    name="right_caster_link">
    <inertial>
      <origin
        xyz="0.0176910999999773 0.0604519999999999 0.0387985"
        rpy="0 0 0" />
      <mass
        value="0.0814912470443749" />
      <inertia
        ixx="5.45189673119832E-05"
        ixy="3.86584233492547E-20"
        ixz="1.59539578754955E-20"
        iyy="3.00969011069377E-05"
        iyz="7.6232965252887E-21"
        izz="3.00969011069377E-05" />
    </inertial>
    <visual>
      <origin
        xyz="0 0 0"
        rpy="0 0 0" />
      <geometry>
        <mesh
          filename="package://final_description/meshes/right_caster_link.STL" />
      </geometry>
      <material
        name="">
        <color
          rgba="0.796078431372549 0.823529411764706 0.937254901960784 1" />
      </material>
    </visual>
    <collision>
      <origin
        xyz="0 0 0"
        rpy="0 0 0" />
      <geometry>
        <mesh
          filename="package://final_description/meshes/right_caster_link.STL" />
      </geometry>
    </collision>
  </link>
  <joint
    name="right_caster_joint"
    type="continuous">
    <origin
      xyz="0.014747 -0.035382 -0.010031"
      rpy="-1.3002 -5.9492E-33 1.5708" />
    <parent
      link="rear_caster_link" />
    <child
      link="right_caster_link" />
    <axis
      xyz="-1 0 0" />
  </joint>
 <gazebo>
    <plugin name="differential_drive_controller" filename="libgazebo_ros_diff_drive.so">
      <leftJoint>left_wheel_joint</leftJoint>
      <rightJoint>right_wheel_joint</rightJoint>
      <robotBaseFrame>base_link</robotBaseFrame>
      <wheelSeparation>0.45</wheelSeparation>
      <wheelDiameter>0.2</wheelDiameter>
      <publishWheelJointState>true</publishWheelJointState>
    </plugin>
  </gazebo>
</robot>
